Workbook

Sheet Опис. статистика
A1: Добыча нефти | C1: Добыча нефти по РФ | E1: Действующие скважины | G1: Инвестиции по региону
A3: Среднее | B3: 27.99375 | C3: Среднее | D3: 528.6125 | E3: Среднее | F3: 20978.188 | G3: Среднее | H3: 119.84375
A4: Стандартная ошибка | B4: 0.54980821 | C4: Стандартная ошибка | D4: 4.1751235 | E4: Стандартная ошибка | F4: 260.36299 | G4: Стандартная ошибка | H4: 17.495492
A5: Медиана | B5: 27.5 | C5: Медиана | D5: 525.4 | E5: Медиана | F5: 20723 | G5: Медиана | H5: 97.5
A6: Мода | B6: 27.2 | C6: Мода | D6: #N/A | E6: Мода | F6: #N/A | G6: Мода | H6: #N/A
A7: Стандартное отклонение | B7: 2.1992328 | C7: Стандартное отклонение | D7: 16.700494 | E7: Стандартное отклонение | F7: 1041.4519 | G7: Стандартное отклонение | H7: 69.981969
A8: Дисперсия выборки | B8: 4.836625 | C8: Дисперсия выборки | D8: 278.9065 | E8: Дисперсия выборки | F8: 1084622.2 | G8: Дисперсия выборки | H8: 4897.476
A9: Эксцесс | B9: 4.3354326 | C9: Эксцесс | D9: -0.70128993 | E9: Эксцесс | F9: -1.2445168 | G9: Эксцесс | H9: 1.1161385
A10: Асимметричность | B10: 1.7635509 | C10: Асимметричность | D10: 0.56741845 | E10: Асимметричность | F10: -0.09436099 | G10: Асимметричность | H10: 1.090285
A11: Интервал | B11: 8.7 | C11: Интервал | D11: 55 | E11: Интервал | F11: 3407 | G11: Интервал | H11: 275.6
A12: Минимум | B12: 25.8 | C12: Минимум | D12: 505.2 | E12: Минимум | F12: 19043 | G12: Минимум | H12: 11.9
A13: Максимум | B13: 34.5 | C13: Максимум | D13: 560.2 | E13: Максимум | F13: 22450 | G13: Максимум | H13: 287.5
A14: Сумма | B14: 447.9 | C14: Сумма | D14: 8457.8 | E14: Сумма | F14: 335651 | G14: Сумма | H14: 1917.5
A15: Счет | B15: 16 | C15: Счет | D15: 16 | E15: Счет | F15: 16 | G15: Счет | H15: 16
A16: Уровень надежности(95,0%) | B16: 1.1718884 | C16: Уровень надежности(95,0%) | D16: 8.8990651 | E16: Уровень надежности(95,0%) | F16: 554.95057 | G16: Уровень надежности(95,0%) | H16: 37.290759

Sheet Регрессия скважины
A1: ВЫВОД ИТОГОВ
A3: Регрессионная статистика
A4: Множественный R | B4: 0.73702772
A5: R-квадрат | B5: 0.54320986
A6: Нормированный R-квадрат | B6: 0.50807216 | D6: Критерий Фишера | E6: =_xlfn.F.INV.RT(0.05,B12,B13) -> 4.6671927
A7: Стандартная ошибка | B7: 727.33153 | D7: Критерий стьюдента | E7: =_xlfn.T.INV.2T(0.05,B13) -> 2.1603687
A8: Наблюдения | B8: 15
A10: Дисперсионный анализ
B11: df | C11: SS | D11: MS | E11: F | F11: Значимость F
A12: Регрессия | B12: 1 | C12: 8178225.9 | D12: 8178225.9 | E12: 15.459458 | F12: 0.0017194629
A13: Остаток | B13: 13 | C13: 6877145 | D13: 529011.15
A14: Итого | B14: 14 | C14: 15055371
B16: Коэффициенты | C16: Стандартная ошибка | D16: t-статистика | E16: P-Значение | F16: Нижние 95% | G16: Верхние 95% | H16: Нижние 95,0% | I16: Верхние 95,0%
A17: Y-пересечение | B17: 19652.749 | C17: 370.18591 | D17: 53.088864 | E17: 1.3806607e-16 | F17: 18853.011 | G17: 20452.487 | H17: 18853.011 | I17: 20452.487
A18: Инвестиции по региону | B18: 10.808733 | C18: 2.7490183 | D18: 3.9318518 | E18: 0.0017194629 | F18: 4.8698395 | G18: 16.747626 | H18: 4.8698395 | I18: 16.747626
A22: ВЫВОД ОСТАТКА
A24: Наблюдение | B24: Предсказанное 22045 | C24: Остатки | D24: Стандартные остатки
A25: 1 | B25: 22201.448 | C25: -226.44842 | D25: -0.32309424
A26: 2 | B26: 22760.26 | C26: -554.25989 | D26: -0.79081223
A27: 3 | B27: 21645.88 | C27: 804.12044 | D27: 1.1473107
A28: 4 | B28: 21039.51 | C28: 1106.4903 | D28: 1.5787289
A29: 5 | B29: 20769.291 | C29: 1045.7086 | D29: 1.4920062
A30: 6 | B30: 21053.561 | C30: 467.43898 | D30: 0.66693706
A31: 7 | B31: 20709.843 | C31: 276.15667 | D31: 0.39401746
A32: 8 | B32: 20617.969 | C32: -1574.9691 | D32: -2.2471495
A33: 9 | B33: 20703.358 | C33: -243.35809 | D33: -0.34722078
A34: 10 | B34: 19781.373 | C34: 409.6268 | D34: 0.58445125
A35: 11 | B35: 20428.816 | C35: -177.81628 | D35: -0.25370642
A36: 12 | B36: 20569.33 | C36: -312.3298 | D36: -0.44562891
... A39: 15 | B39: 20606.079 | C39: -368.07949 | D39: -0.52517199

Sheet Корреляция
B1: Добыча нефти | C1: Добыча по РФ | D1: Действующие скважины | E1: Инвестиции
A2: Добыча нефти | B2: 1
A3: Добыча по РФ | B3: -0.31840819 | C3: 1
A4: Действующие скважины | B4: 0.38664705 | C4: -0.59181989 | D4: 1
A5: Инвестиции | B5: 0.37783682 | C5: -0.35792827 | D5: 0.7392323 | E5: 1
A7: Мультиколлениарность

Sheet Оценка качества модели
A1: Год | B1: Действующие скважины, тыс. | C1: Инвестиционный по региону млрд. рублей | F1: Прогноз | G1: Остаточная компонента | H1: Остаток^2 I Дисперсия | N1: Ошибка аппроксимации | Q1: Критерий Стьюдента | W1: Ассиммтерия | X1: Эксцесс | AA1: Критерий Дарбина-Уотсона | AC1: =SUM(AA3:AA17)/SUM(H2:H16) -> 1.16448
A2: 2010 | B2: 20238 | C2: 88.2 | F2: ='Регрессия скважины'!$B$17+'Регрессия скважины'!$B$18*'Оценка качества модели'!C2 -> 20606.079 | G2: =B2-F2 -> -368.07949 | H2: =POWER(G2,2) -> 135482.51 | I2: 0 | N2: =ABS(G2/B2) -> 0.018187543 | Q2: =ABS(AVERAGE(G2:G16)/_xlfn.STDEV.S(G2:G16))*SQRT(15) -> 0.41807863 | T2: Р | U2: =SUM(I2:I16) -> 8 | W2: =SKEW(G2:G16) -> 0.013642269 | X2: =KURT(G2:G16) -> 0.23854907
A3: 2011 | B3: 20246 | C3: 67.2 | F3: ='Регрессия скважины'!$B$17+'Регрессия скважины'!$B$18*'Оценка качества модели'!C3 -> 20379.096 | G3: =B3-F3 -> -133.09611 | H3: =POWER(G3,2) -> 17714.575 | I3: =IF(OR(AND(G3>G2, G3>G4), AND(G3<G2, G3<G4)), 1, 0) -> 1 | N3: =ABS(G3/B3) -> 0.006573946 | Q3: Табличное значение | T3: p̅ | U3: ζ^2 | W3: СКО ассимтерия | X3: СКО эксцесс | AA3: =(G3-G2)^2 -> 55217.19
A4: 2012 | B4: 19821 | C4: 63.6 | F4: ='Регрессия скважины'!$B$17+'Регрессия скважины'!$B$18*'Оценка качества модели'!C4 -> 20340.185 | G4: =B4-F4 -> -519.18467 | H4: =POWER(G4,2) -> 269552.73 | I4: =IF(OR(AND(G4>G3, G4>G5), AND(G4<G3, G4<G5)), 1, 0) -> 1 | N4: =ABS(G4/B4) -> 0.026193667 | Q4: =TINV(0.05,15-3) -> 2.1788128 | T4: =2*(15-2)/3 -> 8.6666667 | U4: =(16*15-29)/90 -> 2.3444444 | W4: =SQRT((6*(15-1))/((15+1)*(15+3))) -> 0.54006172 | X4: =SQRT((24*15*(15-2)*(15-3))/((15+3)*(15+5)*(15-1)^2)) -> 0.89214257 | AA4: =(G4-G3)^2 -> 149064.38
A5: 2013 | B5: 20257 | C5: 84.8 | F5: ='Регрессия скважины'!$B$17+'Регрессия скважины'!$B$18*'Оценка качества модели'!C5 -> 20569.33 | G5: =B5-F5 -> -312.3298 | H5: =POWER(G5,2) -> 97549.906 | I5: =IF(OR(AND(G5>G4, G5>G6), AND(G5<G4, G5<G6)), 1, 0) -> 0 | N5: =ABS(G5/B5) -> 0.015418364 | T5: p̅-t | U5: =T4-Q4 -> 6.4878538 | AA5: =(G5-G4)^2 -> 42788.937
A6: 2014 | B6: 20251 | C6: 71.8 | F6: ='Регрессия скважины'!$B$17+'Регрессия скважины'!$B$18*'Оценка качества модели'!C6 -> 20428.816 | G6: =B6-F6 -> -177.81628 | H6: =POWER(G6,2) -> 31618.63 | I6: =IF(OR(AND(G6>G5, G6>G7), AND(G6<G5, G6<G7)), 1, 0) -> 1 | N6: =ABS(G6/B6) -> 0.0087806173 | U6: =T4-Q4*SQRT(U4) -> 5.3305602 | AA6: =(G6-G5)^2 -> 18093.888
A7: 2015 | B7: 20191 | C7: 119.2 | F7: ='Регрессия скважины'!$B$17+'Регрессия скважины'!$B$18*'Оценка качества модели'!C7 -> 20941.15 | G7: =B7-F7 -> -750.1502 | H7: =POWER(G7,2) -> 562725.33 | I7: =IF(OR(AND(G7>G6, G7>G8), AND(G7<G6, G7<G8)), 1, 0) -> 1 | N7: =ABS(G7/B7) -> 0.037152702 | AA7: =(G7-G6)^2 -> 327566.12
A8: 2016 | B8: 20460 | C8: 97.2 | F8: ='Регрессия скважины'!$B$17+'Регрессия скважины'!$B$18*'Оценка качества модели'!C8 -> 20703.358 | G8: =B8-F8 -> -243.35809 | H8: =POWER(G8,2) -> 59223.159 | I8: =IF(OR(AND(G8>G7, G8>G9), AND(G8<G7, G8<G9)), 1, 0) -> 1 | N8: =ABS(G8/B8) -> 0.011894335 | AA8: =(G8-G7)^2 -> 256838.25
A9: 2017 | B9: 19043 | C9: 89.3 | F9: ='Регрессия скважины'!$B$17+'Регрессия скважины'!$B$18*'Оценка качества модели'!C9 -> 20617.969 | G9: =B9-F9 -> -1574.9691 | H9: =POWER(G9,2) -> 2480527.7 | I9: =IF(OR(AND(G9>G8, G9>G10), AND(G9<G8, G9<G10)), 1, 0) -> 1 | N9: =ABS(G9/B9) -> 0.082705934 | AA9: =(G9-G8)^2 -> 1773187.9
A10: 2018 | B10: 20986 | C10: 97.8 | F10: ='Регрессия скважины'!$B$17+'Регрессия скважины'!$B$18*'Оценка качества модели'!C10 -> 20709.843 | G10: =B10-F10 -> 276.15667 | H10: =POWER(G10,2) -> 76262.508 | I10: =IF(OR(AND(G10>G9, G10>G11), AND(G10<G9, G10<G11)), 1, 0) -> 0 | N10: =ABS(G10/B10) -> 0.01315909 | AA10: =(G10-G9)^2 -> 3426666.6
A11: 2019 | B11: 21521 | C11: 129.6 | F11: ='Регрессия скважины'!$B$17+'Регрессия скважины'!$B$18*'Оценка качества модели'!C11 -> 21053.561 | G11: =B11-F11 -> 467.43898 | H11: =POWER(G11,2) -> 218499.2 | I11: =IF(OR(AND(G11>G10, G11>G12), AND(G11<G10, G11<G12)), 1, 0) -> 0 | N11: =ABS(G11/B11) -> 0.021720133 | AA11: =(G11-G10)^2 -> 36588.92
A12: 2020 | B12: 21815 | C12: 103.3 | F12: ='Регрессия скважины'!$B$17+'Регрессия скважины'!$B$18*'Оценка качества модели'!C12 -> 20769.291 | G12: =B12-F12 -> 1045.7086 | H12: =POWER(G12,2) -> 1093506.6 | I12: =IF(OR(AND(G12>G11, G12>G13), AND(G12<G11, G12<G13)), 1, 0) -> 0 | N12: =ABS(G12/B12) -> 0.047935303 | AA12: =(G12-G11)^2 -> 334395.81
A13: 2021 | B13: 22146 | C13: 128.3 | F13: ='Регрессия скважины'!$B$17+'Регрессия скважины'!$B$18*'Оценка качества модели'!C13 -> 21039.51 | G13: =B13-F13 -> 1106.4903 | H13: =POWER(G13,2) -> 1224320.9 | I13: =IF(OR(AND(G13>G12, G13>G14), AND(G13<G12, G13<G14)), 1, 0) -> 1 | N13: =ABS(G13/B13) -> 0.049963439 | AA13: =(G13-G12)^2 -> 3694.4134
A14: 2022 | B14: 22450 | C14: 184.4 | F14: ='Регрессия скважины'!$B$17+'Регрессия скважины'!$B$18*'Оценка качества модели'!C14 -> 21645.88 | G14: =B14-F14 -> 804.12044 | H14: =POWER(G14,2) -> 646609.67 | I14: =IF(OR(AND(G14>G13, G14>G15), AND(G14<G13, G14<G15)), 1, 0) -> 0 | N14: =ABS(G14/B14) -> 0.035818282 | AA14: =(G14-G13)^2 -> 91427.554
A15: 2023 | B15: 22206 | C15: 287.5 | F15: ='Регрессия скважины'!$B$17+'Регрессия скважины'!$B$18*'Оценка качества модели'!C15 -> 22760.26 | G15: =B15-F15 -> -554.25989 | H15: =POWER(G15,2) -> 307204.03 | I15: =IF(OR(AND(G15>G14, G15>G16), AND(G15<G14, G15<G16)), 1, 0) -> 1 | N15: =ABS(G15/B15) -> 0.024959916 | AA15: =(G15-G14)^2 -> 1845197.1
A16: 2024 | B16: 21975 | C16: 235.8 | F16: ='Регрессия скважины'!$B$17+'Регрессия скважины'!$B$18*'Оценка качества модели'!C16 -> 22201.448 | G16: =B16-F16 -> -226.44842 | H16: =POWER(G16,2) -> 51278.886 | I16: =IF(OR(AND(G16>G15, G16>G17), AND(G16<G15, G16<G17)), 1, 0) -> 0 | N16: =ABS(G16/B16) -> 0.01030482 | O16: Ошибка | AA16: =(G16-G15)^2 -> 107460.36
A17: 2025 | B17: 22045 | C17: 176.8 | F17: ='Регрессия скважины'!$B$17+'Регрессия скважины'!$B$18*'Оценка качества модели'!C17 -> 21563.733 | G17: =B17-F17 -> 481.2668 | H17: =POWER(G17,2) -> 231617.74 | I17: 0 | N17: =ABS(G17/B17) -> 0.021831109 | O17: =AVERAGE(N2:N17) -> 0.02703745
I18: Дисперсия остатков | J18: =SUM(H2:H17)/(15-2) -> 577207.23
I19: Дисперсия исходного ряда | J19: =_xlfn.VAR.S(B2:B17) -> 1084622.2
I20: Коэфф сходимости | J20: =J18/J19 -> 0.53217355
I21: Коэфф эмпирической детерминации | J21: =1-J20 -> 0.46782645
I22: Индекс корреляции | J22: =SQRT(J21) -> 0.6839784
P25: Критерий Стьюдента
P26: 3.0128593e-14
P27: Табличное значение
P28: 2.1788128

Sheet Лист4
A1: ВЫВОД ИТОГОВ
A3: Регрессионная статистика
A4: Множественный R | B4: 0.37562906 | E4: Критерий Фишера | F4: =_xlfn.F.INV.RT(0.05,B12,B13) -> 3.8852938
A5: R-квадрат | B5: 0.14109719 | E5: Критерий Стьюдента | F5: =_xlfn.T.INV.2T(0.05,B13) -> 2.1788128
A6: Нормированный R-квадрат | B6: -0.0020532768
A7: Стандартная ошибка | B7: 2.1966602
A8: Наблюдения | B8: 15
A10: Дисперсионный анализ
B11: df | C11: SS | D11: MS | E11: F | F11: Значимость F
A12: Регрессия | B12: 2 | C12: 9.5122082 | D12: 4.7561041 | E12: 0.98565651 | F12: 0.40148021
A13: Остаток | B13: 12 | C13: 57.903792 | D13: 4.825316
A14: Итого | B14: 14 | C14: 67.416
B16: Коэффициенты | C16: Стандартная ошибка | D16: t-статистика | E16: P-Значение | F16: Нижние 95% | G16: Верхние 95% | H16: Нижние 95,0% | I16: Верхние 95,0%
A17: Y-пересечение | B17: 26.687278 | C17: 32.896245 | D17: 0.81125606 | E17: 0.43301536 | F17: -44.987483 | G17: 98.362039 | H17: -44.987483 | I17: 98.362039
A18: Добыча нефти по РФ | B18: -0.019236081 | C18: 0.042155287 | D18: -0.45631478 | E18: 0.65631227 | F18: -0.11108456 | G18: 0.0726124 | H18: -0.11108456 | I18: 0.0726124
A19: Действующие скважины | B19: 0.00055233513 | C19: 0.0006859189 | D19: 0.80524846 | E19: 0.43634167 | F19: -0.00094215376 | G19: 0.002046824 | H19: -0.00094215376 | I19: 0.002046824
A23: ВЫВОД ОСТАТКА
A25: Наблюдение | B25: Предсказанное 25,8 | C25: Остатки
A26: 1 | B26: 27.790149 | C26: -1.8901491
A27: 2 | B27: 27.772774 | C27: -1.4727744
A28: 3 | B28: 27.099879 | C28: -0.69987871
A29: 4 | B29: 27.181203 | C29: -0.68120346
A30: 5 | B30: 27.321188 | C30: -0.12118807
A31: 6 | B31: 27.456301 | C31: 1.143699
A32: 7 | B32: 26.931406 | C32: 1.9685944
A33: 8 | B33: 28.145016 | C33: 1.3549839
A34: 9 | B34: 28.507842 | C34: 1.2921583
A35: 10 | B35: 28.772179 | C35: -2.7721795
A36: 11 | B36: 29.081961 | C36: -1.2819605
A37: 12 | B37: 29.369134 | C37: -0.2691341
... A40: 15 | B40: 29.014633 | C40: 5.485367

Sheet Регрессия Инв и Рф
A1: ВЫВОД ИТОГОВ
A3: Регрессионная статистика
A4: Множественный R | B4: 0.4035712 | D4: Критерий Фишера | E4: =_xlfn.F.INV.RT(0.05,B12,B13) -> 3.8852938
A5: R-квадрат | B5: 0.16286971 | D5: Критерий Стьюдента | E5: =_xlfn.T.INV.2T(0.05,B13) -> 2.1788128
A6: Нормированный R-квадрат | B6: 0.023347998
A7: Стандартная ошибка | B7: 2.1686397
A8: Наблюдения | B8: 15
A10: Дисперсионный анализ
B11: df | C11: SS | D11: MS | E11: F | F11: Значимость F
A12: Регрессия | B12: 2 | C12: 10.980025 | D12: 5.4900123 | E12: 1.1673431 | F12: 0.34415836
A13: Остаток | B13: 12 | C13: 56.435975 | D13: 4.702998
A14: Итого | B14: 14 | C14: 67.416
B16: Коэффициенты | C16: Стандартная ошибка | D16: t-статистика | E16: P-Значение | F16: Нижние 95% | G16: Верхние 95% | H16: Нижние 95,0% | I16: Верхние 95,0%
A17: Добыча нефти (Y) | B17: 41.074491 | C17: 19.447988 | D17: 2.1120175 | E17: 0.056329172 | F17: -1.2990353 | G17: 83.448017 | H17: -1.2990353 | I17: 83.448017
A18: Добыча нефти по РФ | B18: -0.026778136 | C18: 0.035924642 | D18: -0.74539744 | E18: 0.47038034 | F18: -0.10505121 | G18: 0.051494935 | H18: -0.10505121 | I18: 0.051494935
A19: Инвестиции по региону | B19: 0.0093809925 | C19: 0.0094888683 | D19: 0.98863134 | E19: 0.34235939 | F19: -0.011293475 | G19: 0.03005546 | H19: -0.011293475 | I19: 0.03005546
A23: ВЫВОД ОСТАТКА
A25: Наблюдение | B25: Предсказанное 25,8 | C25: Остатки
A26: 1 | B26: 27.67315 | C26: -1.7731504
A27: 2 | B27: 27.941972 | C27: -1.6419717
A28: 3 | B28: 26.868887 | C28: -0.46888731
A29: 4 | B29: 26.864758 | C29: -0.36475821
A30: 5 | B30: 27.55042 | C30: -0.35042047
A31: 6 | B31: 27.325294 | C31: 1.2747061
A32: 7 | B32: 27.610011 | C32: 1.2899889
A33: 8 | B33: 27.88523 | C33: 1.61477
A34: 9 | B34: 28.277269 | C34: 1.522731
A35: 10 | B35: 28.172473 | C35: -2.172473
A36: 11 | B36: 28.583734 | C36: -0.78373352
A37: 12 | B37: 29.276032 | C37: -0.17603164
... A40: 15 | B40: 29.022645 | C40: 5.4773552

Sheet Лист2
A1: ВЫВОД ИТОГОВ
A3: Регрессионная статистика
A4: Множественный R | B4: 0.4063682
A5: R-квадрат | B5: 0.16513511
A6: Нормированный R-квадрат | B6: -0.062555308 | D6: Критерий Фишера | E6: =_xlfn.F.INV.RT(0.05,B12,B13) -> 3.5874337
A7: Стандартная ошибка | B7: 2.2620034 | D7: Критерий Стьюдента | E7: =_xlfn.T.INV.2T(0.05,B13) -> 2.2009852
A8: Наблюдения | B8: 15
A10: Дисперсионный анализ
B11: df | C11: SS | D11: MS | E11: F | F11: Значимость F
A12: Регрессия | B12: 3 | C12: 11.132749 | D12: 3.7109163 | E12: 0.72526157 | F12: 0.55780935
A13: Остаток | B13: 11 | C13: 56.283251 | D13: 5.1166592
A14: Итого | B14: 14 | C14: 67.416
B16: Коэффициенты | C16: Стандартная ошибка | D16: t-статистика | E16: P-Значение | F16: Нижние 95% | G16: Верхние 95% | H16: Нижние 95,0% | I16: Верхние 95,0%
A17: Y-пересечение | B17: 35.640896 | C17: 37.424861 | D17: 0.95233209 | E17: 0.36138623 | F17: -46.730667 | G17: 118.01246 | H17: -46.730667 | I17: 118.01246
A18: Добыча по РФ | B18: -0.022834111 | C18: 0.043877546 | D18: -0.52040538 | E18: 0.61309447 | F18: -0.11940794 | G18: 0.073739717 | H18: -0.11940794 | I18: 0.073739717
A19: Инвестиции по региону | B19: 0.0077338676 | C19: 0.013742318 | D19: 0.56277749 | E19: 0.58487379 | F19: -0.022512772 | G19: 0.037980507 | H19: -0.022512772 | I19: 0.037980507
A20: Действующие скважины | B20: 0.00016943525 | C20: 0.00098071513 | D20: 0.17276704 | E20: 0.86597241 | F20: -0.0019891042 | G20: 0.0023279747 | H20: -0.0019891042 | I20: 0.0023279747
A24: ВЫВОД ОСТАТКА
A26: Наблюдение | B26: Предсказанное 25,8 | C26: Остатки
A27: 1 | B27: 27.625924 | C27: -1.7259238
A28: 2 | B28: 27.784097 | C28: -1.4840974
A29: 3 | B29: 26.937309 | C29: -0.53730887
A30: 4 | B30: 26.936222 | C30: -0.43622206
A31: 5 | B31: 27.498148 | C31: -0.29814827
A32: 6 | B32: 27.357597 | C32: 1.2424026
A33: 7 | B33: 27.362387 | C33: 1.5376128
A34: 8 | B34: 27.924027 | C34: 1.5759732
A35: 9 | B35: 28.340531 | C35: 1.459469
A36: 10 | B36: 28.307965 | C36: -2.307965
A37: 11 | B37: 28.7081 | C37: -0.90809991
A38: 12 | B38: 29.33505 | C38: -0.23504969
... A41: 15 | B41: 29.052379 | C41: 5.4476209

Sheet Данные
A1: Год | B1: Объем добычи нефти (млн тонн) | C1: Добыча нефти по РФ, млн. тонн | D1: Действующие скважины, тыс. | E1: Инвестиционный по региону млрд. рублей | F1: Добыча нефти на одну скважину | T1: Объем добычи нефти (млн тонн) | U1: Добыча нефти по РФ, млн. тонн | V1: Инвестиционный по региону млрд. рублей | W1: Действующие скважины, тыс.
A2: 2010 | B2: 25.8 | C2: 534 | D2: 20238 | E2: 88.2 | F2: =B2/D2 -> 0.0012748295 | T2: 25.8 | U2: 534 | V2: 88.2 | W2: 20238
A3: 2011 | B3: 25.9 | C3: 524 | D3: 20246 | E3: 67.2 | F3: =B3/D3 -> 0.001279265 | T3: 25.9 | U3: 524 | V3: 67.2 | W3: 20246
A4: 2012 | B4: 26.3 | C4: 512.7 | D4: 19821 | E4: 63.6 | F4: =B4/D4 -> 0.0013268755 | T4: 26.3 | U4: 512.7 | V4: 63.6 | W4: 19821
A5: 2013 | B5: 26.4 | C5: 560.2 | D5: 20257 | E5: 84.8 | F5: =B5/D5 -> 0.0013032532 | T5: 26.4 | U5: 560.2 | V5: 84.8 | W5: 20257
A6: 2014 | B6: 26.5 | C6: 555.8 | D6: 20251 | E6: 71.8 | F6: =B6/D6 -> 0.0013085774 | T6: 26.5 | U6: 555.8 | V6: 71.8 | W6: 20251
A7: 2015 | B7: 27.2 | C7: 546.8 | D7: 20191 | E7: 119.2 | F7: =B7/D7 -> 0.0013471349 | S7: 2015 | T7: 27.2 | U7: 546.8 | V7: 119.2 | W7: 20191
A8: 2016 | B8: 28.6 | C8: 547.5 | D8: 20460 | E8: 97.2 | F8: =B8/D8 -> 0.0013978495 | T8: 28.6 | U8: 547.5 | V8: 97.2 | W8: 20460
A9: 2017 | B9: 28.9 | C9: 534.1 | D9: 19043 | E9: 89.3 | F9: =B9/D9 -> 0.001517618 | T9: 28.9 | U9: 534.1 | V9: 89.3 | W9: 19043
A10: 2018 | B10: 29.5 | C10: 526.8 | D10: 20986 | E10: 97.8 | F10: =B10/D10 -> 0.001405699 | T10: 29.5 | U10: 526.8 | V10: 97.8 | W10: 20986
A11: 2019 | B11: 29.8 | C11: 523.3 | D11: 21521 | E11: 129.6 | F11: =B11/D11 -> 0.001384694 | T11: 29.8 | U11: 523.3 | V11: 129.6 | W11: 21521
A12: 2020 | B12: 26 | C12: 518 | D12: 21815 | E12: 103.3 | F12: =B12/D12 -> 0.0011918405 | T12: 26 | U12: 518 | V12: 103.3 | W12: 21815
A13: 2021 | B13: 27.8 | C13: 511.4 | D13: 22146 | E13: 128.3 | F13: =B13/D13 -> 0.0012553057 | S13: 2021 | T13: 27.8 | U13: 511.4 | V13: 128.3 | W13: 22146
A14: 2022 | B14: 29.1 | C14: 505.2 | D14: 22450 | E14: 184.4 | F14: =B14/D14 -> 0.0012962138 | T14: 29.1 | U14: 505.2 | V14: 184.4 | W14: 22450
A15: 2023 | B15: 28.4 | C15: 530 | D15: 22206 | E15: 287.5 | F15: =B15/D15 -> 0.0012789336 | T15: 28.4 | U15: 530 | V15: 287.5 | W15: 22206
A16: 2024 | B16: 27.2 | C16: 516 | D16: 21975 | E16: 235.8 | F16: =B16/D16 -> 0.0012377702 | T16: 27.2 | U16: 516 | V16: 235.8 | W16: 21975
A17: 2025 | B17: 34.5 | C17: 512 | D17: 22045 | E17: 176.8 | F17: =B17/D17 -> 0.0015649807 | G17: Прогноз добычи нефти на 2029 год | T17: 34.5 | U17: 512 | V17: 176.8 | W17: 22045
A18: 2026 | D18: =AVERAGE(D2:D17) -> 20978.188 | E18: =AVERAGE(E2:E17) -> 126.55 | F18: =_xlfn.FORECAST.LINEAR(A18,F2:F17,A2:A17) -> 0.0013596945 | G18: =F18*G38 -> 29.540812 | T18: 28.8 | W18: 21726.065
A19: 2027 | F19: =_xlfn.FORECAST.LINEAR(A19,F3:F18,A3:A18) -> 0.0013565716 | G19: =F19*G39 -> 29.630285 | T19: 28.9 | W19: 21842.036
A20: 2028 | F20: =_xlfn.FORECAST.LINEAR(A20,F4:F19,A4:A19) -> 0.0013512116 | G20: =F20*G40 -> 29.669913 | T20: 29 | W20: 21958.006
A21: 2029 | C21: Инвестиции прогноз! | F21: =_xlfn.FORECAST.LINEAR(A21,F5:F20,A5:A20) -> 0.0013497205 | G21: =F21*G41 -> 29.793699 | T21: 29.1 | W21: 22073.976
B22: 2010 | C22: 88.2 | D22: 1 | E22: =19652.7+10.8*C22 -> 20605.26
B23: 2011 | C23: 67.2 | D23: 2 | E23: =19652.7+10.8*C23 -> 20378.46
B24: 2012 | C24: 63.6 | D24: 3 | E24: =19652.7+10.8*C24 -> 20339.58
B25: 2013 | C25: 84.8 | D25: 4 | E25: =19652.7+10.8*C25 -> 20568.54
B26: 2014 | C26: 71.8 | D26: 5 | E26: =19652.7+10.8*C26 -> 20428.14 | V26: Проноз нефти до 2029 | W26: 510.9976 | X26: 515.9972 | Y26: 524.9948 | Z26: 524.9962
B27: 2015 | C27: 119.2 | D27: 6 | E27: =19652.7+10.8*C27 -> 20940.06
B28: 2016 | C28: 97.2 | D28: 7 | E28: =19652.7+10.8*C28 -> 20702.46
B29: 2017 | C29: 89.3 | D29: 8 | E29: =19652.7+10.8*C29 -> 20617.14
B30: 2018 | C30: 97.8 | D30: 9 | E30: =19652.7+10.8*C30 -> 20708.94
B31: 2019 | C31: 129.6 | D31: 10 | E31: =19652.7+10.8*C31 -> 21052.38
B32: 2020 | C32: 103.3 | D32: 11 | E32: =19652.7+10.8*C32 -> 20768.34
B33: 2021 | C33: 128.3 | D33: 12 | E33: =19652.7+10.8*C33 -> 21038.34
B34: 2022 | C34: 184.4 | D34: 13 | E34: =19652.7+10.8*C34 -> 21644.22
B35: 2023 | C35: 287.5 | D35: 14 | E35: =19652.7+10.8*C35 -> 22757.7
B36: 2024 | C36: 235.8 | D36: 15 | E36: =19652.7+10.8*C36 -> 22199.34
B37: 2025 | C37: 176.8 | D37: 16 | E37: =19652.7+10.8*C37 -> 21562.14 | F37: 2026 - 2025
B38: 2026 | C38: =10.738*D38-35.277 -> 147.269 | D38: 17 | E38: =19652.7+10.8*C38 -> 21243.205 | F38: =E38-E37 -> -318.9348 | G38: =F38+D17 -> 21726.065
B39: 2027 | C39: =10.738*D39-35.277 -> 158.007 | D39: 18 | E39: =19652.7+10.8*C39 -> 21359.176 | F39: =E39-E38 -> 115.9704 | G39: =G38+F39 -> 21842.036
B40: 2028 | C40: =10.738*D40-35.277 -> 168.745 | D40: 19 | E40: =19652.7+10.8*C40 -> 21475.146 | F40: =E40-E39 -> 115.9704 | G40: =G39+F40 -> 21958.006
...
